Workbook

Sheet 0 Read me
B1: The collateral rule by hand: the whole project on a tiny task
B3: Each sheet is one step. Work through them in order: 1 Task, 2 One head, 3 Two heads, 4 Why R heads,
B4: 5 Collateral value, 6 The rule, 7 Backup heads.
B6: Colours: yellow = an input you may change (blue numbers) blue = left matrix orange = top matrix
B7: green = the product (a formula) grey = other computed cells
B9: How to read an L-shape. To multiply A times B, put B above and to the right, A below and to the left.
B10: Each green cell sits in A's row and B's column: multiply them entry by entry and add. Try it below,
B11: then click any green cell to see the formula Excel uses: it is exactly your hand calculation.
F13: B
F14: col 1 | G14: col 2
F15: 5 | G15: 6
C16: A | F16: 7 | G16: 8
B17: row 1 | C17: 1 | D17: 2 | F17: =C17*F15+D17*F16 -> 19 | G17: =C17*G15+D17*G16 -> 22
B18: row 2 | C18: 3 | D18: 4 | F18: =C18*F15+D18*F16 -> 43 | G18: =C18*G15+D18*G16 -> 50
F19: A B
B21: By hand: row 1 times col 1 = 1*5 + 2*7 = 19. row 2 times col 2 = 3*6 + 4*8 = 50.
B23: The tiny task: 4 memory slots, 2 distances (1 and 3), one number per item. The real experiments use
B24: 16 slots, 4 distances (1, 5, 9, 13), 16 numbers per item and 32 heads: same steps, bigger matrices.

Sheet 1 Task
B1: Step 1. The task
B2: A memory of 4 slots holds one item each. A query names a position p and must return the items
B3: 1 and 3 slots ahead, counting round like a clock (mod 4). Change the yellow cells and watch the targets.
B5: slot j | C5: 0 | D5: 1 | E5: 2 | F5: 3
B6: item c_j | C6: 2 | D6: 1 | E6: -3 | F6: 6
B9: query i | C9: p | D9: p + 1 | E9: (p+1) mod 4 | F9: target 1 | G9: p + 3 | H9: (p+3) mod 4 | I9: target 2
B10: 0 | C10: 2 | D10: =C10+1 -> 3 | E10: =MOD(D10,4) -> 3 | F10: =INDEX($C$6:$F$6,E10+1) -> 6 | G10: =C10+3 -> 5 | H10: =MOD(G10,4) -> 1 | I10: =INDEX($C$6:$F$6,H10+1) -> 1
B11: 1 | C11: 0 | D11: =C11+1 -> 1 | E11: =MOD(D11,4) -> 1 | F11: =INDEX($C$6:$F$6,E11+1) -> 1 | G11: =C11+3 -> 3 | H11: =MOD(G11,4) -> 3 | I11: =INDEX($C$6:$F$6,H11+1) -> 6
B12: 2 | C12: 3 | D12: =C12+1 -> 4 | E12: =MOD(D12,4) -> 0 | F12: =INDEX($C$6:$F$6,E12+1) -> 2 | G12: =C12+3 -> 6 | H12: =MOD(G12,4) -> 2 | I12: =INDEX($C$6:$F$6,H12+1) -> -3
B13: 3 | C13: 1 | D13: =C13+1 -> 2 | E13: =MOD(D13,4) -> 2 | F13: =INDEX($C$6:$F$6,E13+1) -> -3 | G13: =C13+3 -> 4 | H13: =MOD(G13,4) -> 0 | I13: =INDEX($C$6:$F$6,H13+1) -> 2
B14: target 1 = the item in slot (p+1) mod 4; target 2 = the item in slot (p+3) mod 4.
B15: By hand: query 0 has p = 2. (2+1) mod 4 = 3, so target 1 = c_3 = 6. (2+3) mod 4 = 1, so target 2 = c_1 = 1.
B16: Why mod: without it p = 2 would need slot 5, which does not exist. Wrapping round gives every query
B17: both answers inside the memory, and 'look 1 ahead' is the same rule at every position.
B19: As matrices (used on the next sheets): memory row j = [one-hot of j | c_j], query row i = one-hot of p_i,
B20: target row i = [c_(p+1) | c_(p+3)]. The real code adds a little noise to every vector.

Sheet 2 One head
B1: Step 2. One attention head, built by hand (it looks 1 slot ahead)
B2: Follow (a) to (f). The head scores every slot, turns the scores into weights that add up to 1, and
B3: returns the weighted average of the items. Try: change W_Q so the 1s move, or lower the sharpness to 1.
B5: (a) Keys: K = Y W_K. W_K keeps each slot's label and ignores its item, so key j = one-hot of j.
I6: W_K
I7: k0 | J7: k1 | K7: k2 | L7: k3
I8: 1 | J8: 0 | K8: 0 | L8: 0
I9: 0 | J9: 1 | K9: 0 | L9: 0
I10: 0 | J10: 0 | K10: 1 | L10: 0
I11: 0 | J11: 0 | K11: 0 | L11: 1
C12: Y (memory) | I12: 0 | J12: 0 | K12: 0 | L12: 0
B13: slot 0 | C13: 1 | D13: 0 | E13: 0 | F13: 0 | G13: ='1 Task'!$C$6 -> 2 | I13: =C13*I8+D13*I9+E13*I10+F13*I11+G13*I12 -> 1 | J13: =C13*J8+D13*J9+E13*J10+F13*J11+G13*J12 -> 0 | K13: =C13*K8+D13*K9+E13*K10+F13*K11+G13*K12 -> 0 | L13: =C13*L8+D13*L9+E13*L10+F13*L11+G13*L12 -> 0
B14: slot 1 | C14: 0 | D14: 1 | E14: 0 | F14: 0 | G14: ='1 Task'!$D$6 -> 1 | I14: =C14*I8+D14*I9+E14*I10+F14*I11+G14*I12 -> 0 | J14: =C14*J8+D14*J9+E14*J10+F14*J11+G14*J12 -> 1 | K14: =C14*K8+D14*K9+E14*K10+F14*K11+G14*K12 -> 0 | L14: =C14*L8+D14*L9+E14*L10+F14*L11+G14*L12 -> 0
B15: slot 2 | C15: 0 | D15: 0 | E15: 1 | F15: 0 | G15: ='1 Task'!$E$6 -> -3 | I15: =C15*I8+D15*I9+E15*I10+F15*I11+G15*I12 -> 0 | J15: =C15*J8+D15*J9+E15*J10+F15*J11+G15*J12 -> 0 | K15: =C15*K8+D15*K9+E15*K10+F15*K11+G15*K12 -> 1 | L15: =C15*L8+D15*L9+E15*L10+F15*L11+G15*L12 -> 0
B16: slot 3 | C16: 0 | D16: 0 | E16: 0 | F16: 1 | G16: ='1 Task'!$F$6 -> 6 | I16: =C16*I8+D16*I9+E16*I10+F16*I11+G16*I12 -> 0 | J16: =C16*J8+D16*J9+E16*J10+F16*J11+G16*J12 -> 0 | K16: =C16*K8+D16*K9+E16*K10+F16*K11+G16*K12 -> 0 | L16: =C16*L8+D16*L9+E16*L10+F16*L11+G16*L12 -> 1
I17: K = Y W_K
B19: (b) Values: V = Y W_V. W_V keeps only the item, so value j = c_j.
I20: W_V
I21: v
I22: 0
I23: 0
I24: 0
I25: 0
C26: Y (memory) | I26: 1
B27: slot 0 | C27: 1 | D27: 0 | E27: 0 | F27: 0 | G27: ='1 Task'!$C$6 -> 2 | I27: =C27*I22+D27*I23+E27*I24+F27*I25+G27*I26 -> 2
B28: slot 1 | C28: 0 | D28: 1 | E28: 0 | F28: 0 | G28: ='1 Task'!$D$6 -> 1 | I28: =C28*I22+D28*I23+E28*I24+F28*I25+G28*I26 -> 1
B29: slot 2 | C29: 0 | D29: 0 | E29: 1 | F29: 0 | G29: ='1 Task'!$E$6 -> -3 | I29: =C29*I22+D29*I23+E29*I24+F29*I25+G29*I26 -> -3
B30: slot 3 | C30: 0 | D30: 0 | E30: 0 | F30: 1 | G30: ='1 Task'!$F$6 -> 6 | I30: =C30*I22+D30*I23+E30*I24+F30*I25+G30*I26 -> 6
I31: V = Y W_V
B33: (c) Queries: Q = X W_Q. Row t of W_Q has its 1 in column (t + 1) mod 4, so the query for p becomes one-hot of p + 1: this head looks 1 ahead.
H34: W_Q (shift by 1)
H35: q0 | I35: q1 | J35: q2 | K35: q3
H36: 0 | I36: 1 | J36: 0 | K36: 0
H37: 0 | I37: 0 | J37: 1 | K37: 0
H38: 0 | I38: 0 | J38: 0 | K38: 1
C39: X (queries, one-hot of p) | H39: 1 | I39: 0 | J39: 0 | K39: 0
B40: p = 2 | C40: =IF('1 Task'!$C$10=0,1,0) -> 0 | D40: =IF('1 Task'!$C$10=1,1,0) -> 0 | E40: =IF('1 Task'!$C$10=2,1,0) -> 1 | F40: =IF('1 Task'!$C$10=3,1,0) -> 0 | H40: =C40*H36+D40*H37+E40*H38+F40*H39 -> 0 | I40: =C40*I36+D40*I37+E40*I38+F40*I39 -> 0 | J40: =C40*J36+D40*J37+E40*J38+F40*J39 -> 0 | K40: =C40*K36+D40*K37+E40*K38+F40*K39 -> 1
B41: p = 0 | C41: =IF('1 Task'!$C$11=0,1,0) -> 1 | D41: =IF('1 Task'!$C$11=1,1,0) -> 0 | E41: =IF('1 Task'!$C$11=2,1,0) -> 0 | F41: =IF('1 Task'!$C$11=3,1,0) -> 0 | H41: =C41*H36+D41*H37+E41*H38+F41*H39 -> 0 | I41: =C41*I36+D41*I37+E41*I38+F41*I39 -> 1 | J41: =C41*J36+D41*J37+E41*J38+F41*J39 -> 0 | K41: =C41*K36+D41*K37+E41*K38+F41*K39 -> 0
B42: p = 3 | C42: =IF('1 Task'!$C$12=0,1,0) -> 0 | D42: =IF('1 Task'!$C$12=1,1,0) -> 0 | E42: =IF('1 Task'!$C$12=2,1,0) -> 0 | F42: =IF('1 Task'!$C$12=3,1,0) -> 1 | H42: =C42*H36+D42*H37+E42*H38+F42*H39 -> 1 | I42: =C42*I36+D42*I37+E42*I38+F42*I39 -> 0 | J42: =C42*J36+D42*J37+E42*J38+F42*J39 -> 0 | K42: =C42*K36+D42*K37+E42*K38+F42*K39 -> 0
B43: p = 1 | C43: =IF('1 Task'!$C$13=0,1,0) -> 0 | D43: =IF('1 Task'!$C$13=1,1,0) -> 1 | E43: =IF('1 Task'!$C$13=2,1,0) -> 0 | F43: =IF('1 Task'!$C$13=3,1,0) -> 0 | H43: =C43*H36+D43*H37+E43*H38+F43*H39 -> 0 | I43: =C43*I36+D43*I37+E43*I38+F43*I39 -> 0 | J43: =C43*J36+D43*J37+E43*J38+F43*J39 -> 1 | K43: =C43*K36+D43*K37+E43*K38+F43*K39 -> 0
...

Sheet 3 Two heads
B1: Step 3. A second head (looks 3 ahead), then both heads through their valves
B2: Head 2 is built exactly like head 1; only W_Q differs (shift by 3). Its output is at the bottom of (f).
B4: (a) Keys: K = Y W_K. W_K keeps each slot's label and ignores its item, so key j = one-hot of j.
I5: W_K
I6: k0 | J6: k1 | K6: k2 | L6: k3
I7: 1 | J7: 0 | K7: 0 | L7: 0
I8: 0 | J8: 1 | K8: 0 | L8: 0
I9: 0 | J9: 0 | K9: 1 | L9: 0
I10: 0 | J10: 0 | K10: 0 | L10: 1
C11: Y (memory) | I11: 0 | J11: 0 | K11: 0 | L11: 0
B12: slot 0 | C12: 1 | D12: 0 | E12: 0 | F12: 0 | G12: ='1 Task'!$C$6 -> 2 | I12: =C12*I7+D12*I8+E12*I9+F12*I10+G12*I11 -> 1 | J12: =C12*J7+D12*J8+E12*J9+F12*J10+G12*J11 -> 0 | K12: =C12*K7+D12*K8+E12*K9+F12*K10+G12*K11 -> 0 | L12: =C12*L7+D12*L8+E12*L9+F12*L10+G12*L11 -> 0
B13: slot 1 | C13: 0 | D13: 1 | E13: 0 | F13: 0 | G13: ='1 Task'!$D$6 -> 1 | I13: =C13*I7+D13*I8+E13*I9+F13*I10+G13*I11 -> 0 | J13: =C13*J7+D13*J8+E13*J9+F13*J10+G13*J11 -> 1 | K13: =C13*K7+D13*K8+E13*K9+F13*K10+G13*K11 -> 0 | L13: =C13*L7+D13*L8+E13*L9+F13*L10+G13*L11 -> 0
B14: slot 2 | C14: 0 | D14: 0 | E14: 1 | F14: 0 | G14: ='1 Task'!$E$6 -> -3 | I14: =C14*I7+D14*I8+E14*I9+F14*I10+G14*I11 -> 0 | J14: =C14*J7+D14*J8+E14*J9+F14*J10+G14*J11 -> 0 | K14: =C14*K7+D14*K8+E14*K9+F14*K10+G14*K11 -> 1 | L14: =C14*L7+D14*L8+E14*L9+F14*L10+G14*L11 -> 0
B15: slot 3 | C15: 0 | D15: 0 | E15: 0 | F15: 1 | G15: ='1 Task'!$F$6 -> 6 | I15: =C15*I7+D15*I8+E15*I9+F15*I10+G15*I11 -> 0 | J15: =C15*J7+D15*J8+E15*J9+F15*J10+G15*J11 -> 0 | K15: =C15*K7+D15*K8+E15*K9+F15*K10+G15*K11 -> 0 | L15: =C15*L7+D15*L8+E15*L9+F15*L10+G15*L11 -> 1
I16: K = Y W_K
B18: (b) Values: V = Y W_V. W_V keeps only the item, so value j = c_j.
I19: W_V
I20: v
I21: 0
I22: 0
I23: 0
I24: 0
C25: Y (memory) | I25: 1
B26: slot 0 | C26: 1 | D26: 0 | E26: 0 | F26: 0 | G26: ='1 Task'!$C$6 -> 2 | I26: =C26*I21+D26*I22+E26*I23+F26*I24+G26*I25 -> 2
B27: slot 1 | C27: 0 | D27: 1 | E27: 0 | F27: 0 | G27: ='1 Task'!$D$6 -> 1 | I27: =C27*I21+D27*I22+E27*I23+F27*I24+G27*I25 -> 1
B28: slot 2 | C28: 0 | D28: 0 | E28: 1 | F28: 0 | G28: ='1 Task'!$E$6 -> -3 | I28: =C28*I21+D28*I22+E28*I23+F28*I24+G28*I25 -> -3
B29: slot 3 | C29: 0 | D29: 0 | E29: 0 | F29: 1 | G29: ='1 Task'!$F$6 -> 6 | I29: =C29*I21+D29*I22+E29*I23+F29*I24+G29*I25 -> 6
I30: V = Y W_V
B32: (c) Queries: Q = X W_Q. Row t of W_Q has its 1 in column (t + 3) mod 4, so the query for p becomes one-hot of p + 3: this head looks 3 ahead.
H33: W_Q (shift by 3)
H34: q0 | I34: q1 | J34: q2 | K34: q3
H35: 0 | I35: 0 | J35: 0 | K35: 1
H36: 1 | I36: 0 | J36: 0 | K36: 0
H37: 0 | I37: 1 | J37: 0 | K37: 0
C38: X (queries, one-hot of p) | H38: 0 | I38: 0 | J38: 1 | K38: 0
B39: p = 2 | C39: =IF('1 Task'!$C$10=0,1,0) -> 0 | D39: =IF('1 Task'!$C$10=1,1,0) -> 0 | E39: =IF('1 Task'!$C$10=2,1,0) -> 1 | F39: =IF('1 Task'!$C$10=3,1,0) -> 0 | H39: =C39*H35+D39*H36+E39*H37+F39*H38 -> 0 | I39: =C39*I35+D39*I36+E39*I37+F39*I38 -> 1 | J39: =C39*J35+D39*J36+E39*J37+F39*J38 -> 0 | K39: =C39*K35+D39*K36+E39*K37+F39*K38 -> 0
B40: p = 0 | C40: =IF('1 Task'!$C$11=0,1,0) -> 1 | D40: =IF('1 Task'!$C$11=1,1,0) -> 0 | E40: =IF('1 Task'!$C$11=2,1,0) -> 0 | F40: =IF('1 Task'!$C$11=3,1,0) -> 0 | H40: =C40*H35+D40*H36+E40*H37+F40*H38 -> 0 | I40: =C40*I35+D40*I36+E40*I37+F40*I38 -> 0 | J40: =C40*J35+D40*J36+E40*J37+F40*J38 -> 0 | K40: =C40*K35+D40*K36+E40*K37+F40*K38 -> 1
B41: p = 3 | C41: =IF('1 Task'!$C$12=0,1,0) -> 0 | D41: =IF('1 Task'!$C$12=1,1,0) -> 0 | E41: =IF('1 Task'!$C$12=2,1,0) -> 0 | F41: =IF('1 Task'!$C$12=3,1,0) -> 1 | H41: =C41*H35+D41*H36+E41*H37+F41*H38 -> 0 | I41: =C41*I35+D41*I36+E41*I37+F41*I38 -> 0 | J41: =C41*J35+D41*J36+E41*J37+F41*J38 -> 1 | K41: =C41*K35+D41*K36+E41*K37+F41*K38 -> 0
B42: p = 1 | C42: =IF('1 Task'!$C$13=0,1,0) -> 0 | D42: =IF('1 Task'!$C$13=1,1,0) -> 1 | E42: =IF('1 Task'!$C$13=2,1,0) -> 0 | F42: =IF('1 Task'!$C$13=3,1,0) -> 0 | H42: =C42*H35+D42*H36+E42*H37+F42*H38 -> 1 | I42: =C42*I35+D42*I36+E42*I37+F42*I38 -> 0 | J42: =C42*J35+D42*J36+E42*J37+F42*J38 -> 0 | K42: =C42*K35+D42*K36+E42*K37+F42*K38 -> 0
H43: Q = X W_Q
...

Sheet 4 Why R heads
B1: Step 4. One head, one equation: why the task needs exactly R heads
B2: A head returns ONE weighted average of the items: one equation in the unknown items. Take query 0's two
B3: unknowns a = c(p+1) and b = c(p+3). Each row of the mixing matrix is one head's recipe.
F5: unknowns (a; b)
F6: value
F7: ='1 Task'!$F$10 -> 6
C8: mixing (one row per head) | F8: ='1 Task'!$I$10 -> 1
B9: head 1 | C9: 1 | D9: 0 | F9: =C9*F7+D9*F8 -> 6
B10: head 2 | C10: 0 | D10: 1 | F10: =C10*F7+D10*F8 -> 1
F11: what the heads hand back
B13: Can we get a and b back from the two values? Only if the two recipes are different:
C14: determinant = m11 m22 - m12 m21 | G14: =(C9*D10-D9*C10) -> 1
C15: recovered a | G15: =IF((C9*D10-D9*C10)=0,"cannot",(D10*F9-D9*F10)/(C9*D10-D9*C10)) -> 6
C16: recovered b | G16: =IF((C9*D10-D9*C10)=0,"cannot",(C9*F10-C10*F9)/(C9*D10-D9*C10)) -> 1
B18: Try: (1) mixing rows (0.5, 0.5) and (0.5, -0.5): still recovered. (2) make head 2 a copy of head 1:
B19: determinant 0, 'cannot'. Two copies give the same equation twice, so they count once.
B21: So with k different heads you can recover k of the R items; the rest stay unknown, and the best loss is
B22: (1 - k/R) x the loss of a model that learned nothing. Checked on a trained model (R = 4, real task):
C24: different heads k | E24: measured loss | G24: predicted (1 - k/4) x 1.008
C25: 4 | E25: 0 | G25: =(1-C25/4)*1.008 -> 0
C26: 3 | E26: 0.254 | G26: =(1-C26/4)*1.008 -> 0.252
C27: 2 | E27: 0.507 | G27: =(1-C27/4)*1.008 -> 0.504
C28: 1 | E28: 0.758 | G28: =(1-C28/4)*1.008 -> 0.756
B30: Source of the measured losses: results/proposal/equations.pkl (experiments/equations_test.py).

Sheet 5 Collateral value
B1: Step 5. The collateral value: what nobody else can cover
B2: Three trained heads. Head A looks 1 ahead, head B looks 3 ahead, head C is an exact COPY of A. Their
B3: outputs are the items they fetch (as in steps 2 and 3). The read-out W_O turns them into the two answers.
B4: A head's collateral value = how much the loss rises when it is removed AND the others re-fit W_O.
B6: Case 1. All heads on.
C7: valves g_A, g_B, g_C | G7: 1 | H7: 1 | I7: 1
G8: W_O
G9: ans 1 | H9: ans 2
G10: 0.5 | H10: 0
G11: 0 | H11: 1
C12: [g_A A | g_B B | g_C C] | G12: 0.5 | H12: 0 | J12: target | M12: squared error
B13: p = 2 | C13: =$G$7*'1 Task'!$F$10 -> 6 | D13: =$H$7*'1 Task'!$I$10 -> 1 | E13: =$I$7*'1 Task'!$F$10 -> 6 | G13: =C13*G10+D13*G11+E13*G12 -> 6 | H13: =C13*H10+D13*H11+E13*H12 -> 1 | J13: ='1 Task'!$F$10 -> 6 | K13: ='1 Task'!$I$10 -> 1 | M13: =(G13-J13)^2 -> 0 | N13: =(H13-K13)^2 -> 0
B14: p = 0 | C14: =$G$7*'1 Task'!$F$11 -> 1 | D14: =$H$7*'1 Task'!$I$11 -> 6 | E14: =$I$7*'1 Task'!$F$11 -> 1 | G14: =C14*G10+D14*G11+E14*G12 -> 1 | H14: =C14*H10+D14*H11+E14*H12 -> 6 | J14: ='1 Task'!$F$11 -> 1 | K14: ='1 Task'!$I$11 -> 6 | M14: =(G14-J14)^2 -> 0 | N14: =(H14-K14)^2 -> 0
B15: p = 3 | C15: =$G$7*'1 Task'!$F$12 -> 2 | D15: =$H$7*'1 Task'!$I$12 -> -3 | E15: =$I$7*'1 Task'!$F$12 -> 2 | G15: =C15*G10+D15*G11+E15*G12 -> 2 | H15: =C15*H10+D15*H11+E15*H12 -> -3 | J15: ='1 Task'!$F$12 -> 2 | K15: ='1 Task'!$I$12 -> -3 | M15: =(G15-J15)^2 -> 0 | N15: =(H15-K15)^2 -> 0
B16: p = 1 | C16: =$G$7*'1 Task'!$F$13 -> -3 | D16: =$H$7*'1 Task'!$I$13 -> 2 | E16: =$I$7*'1 Task'!$F$13 -> -3 | G16: =C16*G10+D16*G11+E16*G12 -> -3 | H16: =C16*H10+D16*H11+E16*H12 -> 2 | J16: ='1 Task'!$F$13 -> -3 | K16: ='1 Task'!$I$13 -> 2 | M16: =(G16-J16)^2 -> 0 | N16: =(H16-K16)^2 -> 0
G17: prediction | M17: loss | N17: =AVERAGE(M13:N16) -> 0
B20: Case 2. A off, W_O unchanged (ordinary importance: nobody re-fits).
C21: valves g_A, g_B, g_C | G21: 0 | H21: 1 | I21: 1
G22: W_O
G23: ans 1 | H23: ans 2
G24: 0.5 | H24: 0
G25: 0 | H25: 1
C26: [g_A A | g_B B | g_C C] | G26: 0.5 | H26: 0 | J26: target | M26: squared error
B27: p = 2 | C27: =$G$21*'1 Task'!$F$10 -> 0 | D27: =$H$21*'1 Task'!$I$10 -> 1 | E27: =$I$21*'1 Task'!$F$10 -> 6 | G27: =C27*G24+D27*G25+E27*G26 -> 3 | H27: =C27*H24+D27*H25+E27*H26 -> 1 | J27: ='1 Task'!$F$10 -> 6 | K27: ='1 Task'!$I$10 -> 1 | M27: =(G27-J27)^2 -> 9 | N27: =(H27-K27)^2 -> 0
B28: p = 0 | C28: =$G$21*'1 Task'!$F$11 -> 0 | D28: =$H$21*'1 Task'!$I$11 -> 6 | E28: =$I$21*'1 Task'!$F$11 -> 1 | G28: =C28*G24+D28*G25+E28*G26 -> 0.5 | H28: =C28*H24+D28*H25+E28*H26 -> 6 | J28: ='1 Task'!$F$11 -> 1 | K28: ='1 Task'!$I$11 -> 6 | M28: =(G28-J28)^2 -> 0.25 | N28: =(H28-K28)^2 -> 0
B29: p = 3 | C29: =$G$21*'1 Task'!$F$12 -> 0 | D29: =$H$21*'1 Task'!$I$12 -> -3 | E29: =$I$21*'1 Task'!$F$12 -> 2 | G29: =C29*G24+D29*G25+E29*G26 -> 1 | H29: =C29*H24+D29*H25+E29*H26 -> -3 | J29: ='1 Task'!$F$12 -> 2 | K29: ='1 Task'!$I$12 -> -3 | M29: =(G29-J29)^2 -> 1 | N29: =(H29-K29)^2 -> 0
B30: p = 1 | C30: =$G$21*'1 Task'!$F$13 -> 0 | D30: =$H$21*'1 Task'!$I$13 -> 2 | E30: =$I$21*'1 Task'!$F$13 -> -3 | G30: =C30*G24+D30*G25+E30*G26 -> -1.5 | H30: =C30*H24+D30*H25+E30*H26 -> 2 | J30: ='1 Task'!$F$13 -> -3 | K30: ='1 Task'!$I$13 -> 2 | M30: =(G30-J30)^2 -> 2.25 | N30: =(H30-K30)^2 -> 0
G31: prediction | M31: loss | N31: =AVERAGE(M27:N30) -> 1.5625
B34: Case 3. A off, W_O re-fitted by hand: C takes A's weight (collateral value of A).
C35: valves g_A, g_B, g_C | G35: 0 | H35: 1 | I35: 1
G36: W_O
G37: ans 1 | H37: ans 2
G38: 0 | H38: 0
G39: 0 | H39: 1
C40: [g_A A | g_B B | g_C C] | G40: 1 | H40: 0 | J40: target | M40: squared error
B41: p = 2 | C41: =$G$35*'1 Task'!$F$10 -> 0 | D41: =$H$35*'1 Task'!$I$10 -> 1 | E41: =$I$35*'1 Task'!$F$10 -> 6 | G41: =C41*G38+D41*G39+E41*G40 -> 6 | H41: =C41*H38+D41*H39+E41*H40 -> 1 | J41: ='1 Task'!$F$10 -> 6 | K41: ='1 Task'!$I$10 -> 1 | M41: =(G41-J41)^2 -> 0 | N41: =(H41-K41)^2 -> 0
B42: p = 0 | C42: =$G$35*'1 Task'!$F$11 -> 0 | D42: =$H$35*'1 Task'!$I$11 -> 6 | E42: =$I$35*'1 Task'!$F$11 -> 1 | G42: =C42*G38+D42*G39+E42*G40 -> 1 | H42: =C42*H38+D42*H39+E42*H40 -> 6 | J42: ='1 Task'!$F$11 -> 1 | K42: ='1 Task'!$I$11 -> 6 | M42: =(G42-J42)^2 -> 0 | N42: =(H42-K42)^2 -> 0
B43: p = 3 | C43: =$G$35*'1 Task'!$F$12 -> 0 | D43: =$H$35*'1 Task'!$I$12 -> -3 | E43: =$I$35*'1 Task'!$F$12 -> 2 | G43: =C43*G38+D43*G39+E43*G40 -> 2 | H43: =C43*H38+D43*H39+E43*H40 -> -3 | J43: ='1 Task'!$F$12 -> 2 | K43: ='1 Task'!$I$12 -> -3 | M43: =(G43-J43)^2 -> 0 | N43: =(H43-K43)^2 -> 0
B44: p = 1 | C44: =$G$35*'1 Task'!$F$13 -> 0 | D44: =$H$35*'1 Task'!$I$13 -> 2 | E44: =$I$35*'1 Task'!$F$13 -> -3 | G44: =C44*G38+D44*G39+E44*G40 -> -3 | H44: =C44*H38+D44*H39+E44*H40 -> 2 | J44: ='1 Task'!$F$13 -> -3 | K44: ='1 Task'!$I$13 -> 2 | M44: =(G44-J44)^2 -> 0 | N44: =(H44-K44)^2 -> 0
G45: prediction | M45: loss | N45: =AVERAGE(M41:N44) -> 0
...

Sheet 6 The rule
B1: Step 6. The rule: close the cheapest head while it is worth less than the price
B2: Every 25 training steps: value every open head, close the cheapest if its value is below the price,
B3: and fade it out slowly. Repeat until every open head is worth more than the price.
B5: price | D5: 1
B7: Round 1 (all three heads open)
C8: A | D8: B | E8: C
B9: value | C9: ='5 Collateral value'!$H$67 -> 0 | D9: ='5 Collateral value'!$H$68 -> 6.25 | E9: ='5 Collateral value'!$H$69 -> 0
B10: cheapest | C10: =MIN(C9:E9) -> 0 | D10: =INDEX(C8:E8,MATCH(C10,C9:E9,0)) -> A
B11: decision | C11: =IF(C10<$D$5,"close "&D10,"stop") -> close A
B13: Round 2 (A closed). Now C is the only head carrying c(p+1), so removing C would lose answer 1 entirely:
C14: A | D14: B | E14: C
B15: value | C15: closed | D15: =D9 -> 6.25 | E15: =SUMPRODUCT('1 Task'!$F$10:$F$13,'1 Task'!$F$10:$F$13)/8 -> 6.25
B16: cheapest | C16: =MIN(D15:E15) -> 6.25 | D16: =INDEX(D14:E14,MATCH(C16,D15:E15,0)) -> B
B17: decision | C17: =IF(C16<$D$5,"close "&D16,"stop") -> stop | D17: (stop = every open head is worth more than the price)
B19: C's value in round 2 = average over both answers of c(p+1)^2 = sum of c(p+1)^2 / 8.
B20: Result: B and C stay, 2 heads for a 2-distance task. Nobody told the rule the answer is 2.
B22: Try: raise the price above both round-2 values. The rule then closes a needed head and the task breaks.
B23: Lower it to 0: nothing is ever closed. In the experiments the price is 3% of a know-nothing model's loss.
B24: In training, a closed head fades out over 100 steps, so the other heads adjust while it goes.

Sheet 7 Backup heads
B1: Step 7. Backup heads when heads can fail
B2: If every head fails (valve forced to 0) with chance p at each step, a spare head is worth keeping when it
B3: is likely to be needed: it works AND fewer than R of the other heads work. Its value with B heads open:
C4: v(B) = (1 - p) / R x P[ Binomial(B - 1, 1 - p) <= R - 1 ]
B6: R (heads needed) | F6: 4
B7: p (chance a head fails) | F7: 0.1
B8: price (fraction of a know-nothing loss) | F8: 0.03
B10: B heads open | D10: P[fewer than R others work] | F10: value v(B) | H10: keep?
B11: 1 | D11: =IF(B11-1<=$F$6-1,1,BINOMDIST($F$6-1,B11-1,1-$F$7,TRUE)) -> 1 | F11: =(1-$F$7)/$F$6*D11 -> 0.225 | H11: =IF(F11>=$F$8,"keep","drop") -> keep
B12: 2 | D12: =IF(B12-1<=$F$6-1,1,BINOMDIST($F$6-1,B12-1,1-$F$7,TRUE)) -> 1 | F12: =(1-$F$7)/$F$6*D12 -> 0.225 | H12: =IF(F12>=$F$8,"keep","drop") -> keep
B13: 3 | D13: =IF(B13-1<=$F$6-1,1,BINOMDIST($F$6-1,B13-1,1-$F$7,TRUE)) -> 1 | F13: =(1-$F$7)/$F$6*D13 -> 0.225 | H13: =IF(F13>=$F$8,"keep","drop") -> keep
B14: 4 | D14: =IF(B14-1<=$F$6-1,1,BINOMDIST($F$6-1,B14-1,1-$F$7,TRUE)) -> 1 | F14: =(1-$F$7)/$F$6*D14 -> 0.225 | H14: =IF(F14>=$F$8,"keep","drop") -> keep
B15: 5 | D15: =IF(B15-1<=$F$6-1,1,BINOMDIST($F$6-1,B15-1,1-$F$7,TRUE)) -> 0.3439 | F15: =(1-$F$7)/$F$6*D15 -> 0.0773775 | H15: =IF(F15>=$F$8,"keep","drop") -> keep
B16: 6 | D16: =IF(B16-1<=$F$6-1,1,BINOMDIST($F$6-1,B16-1,1-$F$7,TRUE)) -> 0.08146 | F16: =(1-$F$7)/$F$6*D16 -> 0.0183285 | H16: =IF(F16>=$F$8,"keep","drop") -> drop
B17: 7 | D17: =IF(B17-1<=$F$6-1,1,BINOMDIST($F$6-1,B17-1,1-$F$7,TRUE)) -> 0.01585 | F17: =(1-$F$7)/$F$6*D17 -> 0.00356625 | H17: =IF(F17>=$F$8,"keep","drop") -> drop
B18: 8 | D18: =IF(B18-1<=$F$6-1,1,BINOMDIST($F$6-1,B18-1,1-$F$7,TRUE)) -> 0.002728 | F18: =(1-$F$7)/$F$6*D18 -> 0.0006138 | H18: =IF(F18>=$F$8,"keep","drop") -> drop
B19: 9 | D19: =IF(B19-1<=$F$6-1,1,BINOMDIST($F$6-1,B19-1,1-$F$7,TRUE)) -> 0.00043165 | F19: =(1-$F$7)/$F$6*D19 -> 9.712125e-05 | H19: =IF(F19>=$F$8,"keep","drop") -> drop
B20: 10 | D20: =IF(B20-1<=$F$6-1,1,BINOMDIST($F$6-1,B20-1,1-$F$7,TRUE)) -> 6.4234e-05 | F20: =(1-$F$7)/$F$6*D20 -> 1.445265e-05 | H20: =IF(F20>=$F$8,"keep","drop") -> drop
B21: 11 | D21: =IF(B21-1<=$F$6-1,1,BINOMDIST($F$6-1,B21-1,1-$F$7,TRUE)) -> 9.1216e-06 | F21: =(1-$F$7)/$F$6*D21 -> 2.05236e-06 | H21: =IF(F21>=$F$8,"keep","drop") -> drop
B22: 12 | D22: =IF(B22-1<=$F$6-1,1,BINOMDIST($F$6-1,B22-1,1-$F$7,TRUE)) -> 1.2484e-06 | F22: =(1-$F$7)/$F$6*D22 -> 2.8089e-07 | H22: =IF(F22>=$F$8,"keep","drop") -> drop
B24: predicted heads kept | F24: =COUNTIF(F11:F22,">="&$F$8) -> 5
B26: By hand (R = 4, p = 0.1): B = 5 needs 'fewer than 4 of the other 4 work' = 1 - 0.9^4 = 0.344,
B27: so v(5) = 0.9/4 x 0.344 = 0.077 > 0.03: keep. B = 6 gives 0.018 < 0.03: drop. Predicted: 5 heads.
B29: Measured in training (3 seeds each), written down BEFORE the runs:
B30: R | D30: p | F30: measured heads kept
B31: 2 | D31: 0.05 | F31: 3, 3, 3
B32: 2 | D32: 0.1 | F32: 3, 3, 3
B33: 2 | D33: 0.2 | F33: 4, 4, 4
B34: 2 | D34: 0.3 | F34: 5, 4, 5
B35: 4 | D35: 0.05 | F35: 5, 5, 4
B36: 4 | D36: 0.1 | F36: 5, 5, 5
B37: 4 | D37: 0.2 | F37: 6, 6, 6
B38: 4 | D38: 0.3 | F38: 7, 7, 7
B40: Source: results/robust (experiments/run.py with --head_dropout). Put R and p above to compare.
